Workbook

Sheet 5 Year Forecast
A1: 5 Year Revenue Forecast
B2: Year 1 | C2: Year 2 | D2: Year 3 | E2: Year 4 | F2: Year 5 | G2: Total
A3: Revenue | B3: =+SUM('36 Month Forecast'!B8:M8) -> 50700 | C3: =+SUM('36 Month Forecast'!N8:Y8) -> 233350 | D3: =+SUM('36 Month Forecast'!Z8:AK8) -> 273000 | E3: =+D3*(1+E14) -> 273000 | F3: =+E3*(1+F14) -> 273000 | G3: =+SUM(B3:F3) -> 1103050
A4: COGS | B4: =+SUM('36 Month Forecast'!B9:M9) -> 0 | C4: =+SUM('36 Month Forecast'!N9:Y9) -> 0 | D4: =+SUM('36 Month Forecast'!Z9:AK9) -> 0 | E4: =+D4*(1+E14) -> 0 | F4: =+E4*(1+F14) -> 0 | G4: =+SUM(B4:F4) -> 0
A5: Gross Income | B5: =+B3-B4 -> 50700 | C5: =+C3-C4 -> 233350 | D5: =+D3-D4 -> 273000 | E5: =+E3-E4 -> 273000 | F5: =+F3-F4 -> 273000 | G5: =+SUM(B5:F5) -> 1103050
A7: Expenses:
A8: Marketing Expenses | B8: =+SUM('36 Month Forecast'!B19:M19) -> 3900 | C8: =+SUM('36 Month Forecast'!N19:Y19) -> 2500 | D8: =+SUM('36 Month Forecast'!Z19:AK19) -> 1300 | G8: =+SUM(B8:F8) -> 7700
A9: Operating Expenses | B9: =+SUM('36 Month Forecast'!B41:M41) -> 257642.45 | C9: =+SUM('36 Month Forecast'!N41:Y41) -> 269985.05 | D9: =+SUM('36 Month Forecast'!Z41:AK41) -> 185391.85 | G9: =+SUM(B9:F9) -> 713019.34
A10: Total Expenses | B10: =+SUM(B8:B9) -> 261542.45 | C10: =+SUM(C8:C9) -> 272485.05 | D10: =+SUM(D8:D9) -> 186691.85 | E10: =+SUM(E8:E9) -> 0 | F10: =+SUM(F8:F9) -> 0 | G10: =+SUM(B10:F10) -> 720719.34
A12: Net Income | B12: =+B5-B10 -> -210842.45 | C12: =+C5-C10 -> -39135.046 | D12: =+D5-D10 -> 86308.154 | E12: =+E5-E10 -> 273000 | F12: =+F5-F10 -> 273000 | G12: =+SUM(B12:F12) -> 382330.66
A14: Year Over Year Growth

Sheet 36 Month Forecast
A1: 36 Month Revenue Forecast
B2: Month 1 | C2: Month 2 | D2: Month 3 | E2: Month 4 | F2: Month 5 | G2: Month 6 | H2: Month 7 | I2: Month 8 | J2: Month 9 | K2: Month 10 | L2: Month 11 | M2: Month 12 | N2: Month 13 | O2: Month 14 | P2: Month 15 | Q2: Month 16 | R2: Month 17 | S2: Month 18 | T2: Month 19 | U2: Month 20 | V2: Month 21 | W2: Month 22 | X2: Month 23 | Y2: Month 24 | Z2: Month 25 | AA2: Month 26 | AB2: Month 27 | AC2: Month 28 | AD2: Month 29 | AE2: Month 30 | AF2: Month 31 | AG2: Month 32 | AH2: Month 33 | AI2: Month 34 | AJ2: Month 35 | AK2: Month 36 | AL2: Total | AN2: Assumptions:
A3: Revenue: | AN3: COGS/Revenue
A4: Average Monthly Rent | C4: 650 | D4: 650 | E4: 650 | F4: 650 | G4: 650 | H4: 650 | I4: 650 | J4: 650 | K4: 650 | L4: 650 | M4: 650 | N4: 650 | O4: 650 | P4: 650 | Q4: 650 | R4: 650 | S4: 650 | T4: 650 | U4: 650 | V4: 650 | W4: 650 | X4: 650 | Y4: 650 | Z4: 650 | AA4: 650 | AB4: 650 | AC4: 650 | AD4: 650 | AE4: 650 | AF4: 650 | AG4: 650 | AH4: 650 | AI4: 650 | AJ4: 650 | AK4: 650
A5: Number Of Units Rented (35 total) | H5: 5 | I5: 8 | J5: 13 | K5: 15 | L5: 17 | M5: 20 | N5: 22 | O5: 24 | P5: 26 | Q5: 28 | R5: 29 | S5: 30 | T5: 31 | U5: 32 | V5: 33 | W5: 34 | X5: 35 | Y5: 35 | Z5: 35 | AA5: 35 | AB5: 35 | AC5: 35 | AD5: 35 | AE5: 35 | AF5: 35 | AG5: 35 | AH5: 35 | AI5: 35 | AJ5: 35 | AK5: 35 | AN5: Loan:
AN6: Proceeds | AO6: 1200000
AN7: Interest Rate | AO7: 0.0776
A8: Total Revenue | B8: =+B4*B5 -> 0 | C8: =+C4*C5 -> 0 | D8: =+D4*D5 -> 0 | E8: =+E4*E5 -> 0 | F8: =+F4*F5 -> 0 | G8: =+G4*G5 -> 0 | H8: =+H4*H5 -> 3250 | I8: =+I4*I5 -> 5200 | ... AK8: =+AK4*AK5 -> 22750 | AL8: =+SUM(B8:AK8) -> 557050 | AN8: Term (months) | AO8: 300
A9: COGS | B9: =+B8*$AO$3 -> 0 | C9: =+C8*$AO$3 -> 0 | D9: =+D8*$AO$3 -> 0 | E9: =+E8*$AO$3 -> 0 | F9: =+F8*$AO$3 -> 0 | G9: =+G8*$AO$3 -> 0 | H9: =+H8*$AO$3 -> 0 | I9: =+I8*$AO$3 -> 0 | ... AK9: =+AK8*$AO$3 -> 0 | AL9: =+SUM(B9:AK9) -> 0
A10: Gross Income | B10: =+B8-B9 -> 0 | C10: =+C8-C9 -> 0 | D10: =+D8-D9 -> 0 | E10: =+E8-E9 -> 0 | F10: =+F8-F9 -> 0 | G10: =+G8-G9 -> 0 | H10: =+H8-H9 -> 3250 | I10: =+I8-I9 -> 5200 | ... AK10: =+AK8-AK9 -> 22750 | AL10: =+SUM(B10:AK10) -> 557050
M11: =SUM(B10:M10) -> 50700 | Y11: =SUM(N10:Y10) -> 233350 | AK11: =SUM(Z10:AK10) -> 273000
A12: Marketing Expenses:
A13: Postcards | AL13: =+SUM(B13:AK13) -> 0
A14: Search | AL14: =+SUM(B14:AK14) -> 0
A15: Social | AL15: =+SUM(B15:AK15) -> 0
A16: Marketing Expenses: | C16: 400 | D16: 400 | E16: 400 | F16: 400 | G16: 400 | H16: 400 | I16: 300 | J16: 300 | K16: 300 | L16: 300 | M16: 300 | N16: 300 | O16: 200 | P16: 200 | Q16: 200 | R16: 200 | S16: 200 | T16: 200 | U16: 200 | V16: 200 | W16: 200 | X16: 200 | Y16: 200 | Z16: 200 | AA16: 100 | AB16: 100 | AC16: 100 | AD16: 100 | AE16: 100 | AF16: 100 | AG16: 100 | AH16: 100 | AI16: 100 | AJ16: 100 | AK16: 100 | AL16: =+SUM(B16:AK16) -> 7700
A17: Other | AL17: =+SUM(B17:AK17) -> 0
A18: Misc. | AL18: =+SUM(B18:AK18) -> 0
A19: Total Marketing Expenses | B19: =+SUM(B13:B18) -> 0 | C19: =+SUM(C13:C18) -> 400 | D19: =+SUM(D13:D18) -> 400 | E19: =+SUM(E13:E18) -> 400 | F19: =+SUM(F13:F18) -> 400 | G19: =+SUM(G13:G18) -> 400 | H19: =+SUM(H13:H18) -> 400 | I19: =+SUM(I13:I18) -> 300 | ... AK19: =+SUM(AK13:AK18) -> 100 | AL19: =+SUM(B19:AK19) -> 7700
M20: =SUM(B19:M19) -> 3900 | Y20: =SUM(N19:Y19) -> 2500 | AK20: =SUM(Z19:AK19) -> 1300
A21: Expenses:
A22: Operating Expenses:
A23: Accounting | C23: 200 | D23: 200 | E23: 200 | F23: 200 | G23: 200 | H23: 200 | I23: 200 | J23: 200 | K23: 200 | L23: 200 | M23: 200 | N23: 200 | O23: 200 | P23: 200 | Q23: 200 | R23: 200 | S23: 200 | T23: 200 | U23: 200 | V23: 200 | W23: 200 | X23: 200 | Y23: 200 | Z23: 200 | AA23: 200 | AB23: 200 | AC23: 200 | AD23: 200 | AE23: 200 | AF23: 200 | AG23: 200 | AH23: 200 | AI23: 200 | AJ23: 200 | AK23: 200 | AL23: =+SUM(B23:AK23) -> 7000
A24: Custodial | H24: 0 | I24: 0 | J24: 0 | K24: 0 | L24: 0 | M24: 0 | N24: 0 | O24: 0 | P24: 0 | Q24: 0 | R24: 0 | S24: 0 | T24: 0 | U24: 0 | V24: 0 | W24: 0 | X24: 0 | Y24: 0 | Z24: 1000 | AA24: 1000 | AB24: 1000 | AC24: 1000 | AD24: 1000 | AE24: 1000 | AF24: 1000 | AG24: 1000 | AH24: 1000 | AI24: 1000 | AJ24: 1000 | AK24: 1000 | AL24: =+SUM(B24:AK24) -> 12000
A25: Depreciation | B25: =+'36 Month Capital Expenditures'!B12 -> 3012.8205 | C25: =+'36 Month Capital Expenditures'!C12 -> 3012.8205 | D25: =+'36 Month Capital Expenditures'!D12 -> 3012.8205 | E25: =+'36 Month Capital Expenditures'!E12 -> 3012.8205 | F25: =+'36 Month Capital Expenditures'!F12 -> 3012.8205 | G25: =+'36 Month Capital Expenditures'!G12 -> 3012.8205 | H25: =+'36 Month Capital Expenditures'!H12 -> 3012.8205 | I25: =+'36 Month Capital Expenditures'!I12 -> 3012.8205 | ... AK25: =+'36 Month Capital Expenditures'!AK12 -> 3012.8205 | AL25: =+SUM(B25:AK25) -> 108461.54
A26: Gas | AL26: =+SUM(B26:AK26) -> 0
A27: Insurance | C27: 500 | D27: 500 | E27: 500 | F27: 500 | G27: 500 | H27: 500 | I27: 500 | J27: 500 | K27: 500 | L27: 500 | M27: 500 | N27: 500 | O27: 500 | P27: 500 | Q27: 500 | R27: 500 | S27: 500 | T27: 500 | U27: 500 | V27: 500 | W27: 500 | X27: 500 | Y27: 500 | Z27: 500 | AA27: 500 | AB27: 500 | AC27: 500 | AD27: 500 | AE27: 500 | AF27: 500 | AG27: 500 | AH27: 500 | AI27: 500 | AJ27: 500 | AK27: 500 | AL27: =+SUM(B27:AK27) -> 17500
A28: Interest | B28: =+$AO$6*$AO$7/12 -> 7760 | C28: =+$AO$6*$AO$7/12 -> 7760 | D28: =+$AO$6*$AO$7/12 -> 7760 | E28: =+$AO$6*$AO$7/12 -> 7760 | F28: =+$AO$6*$AO$7/12 -> 7760 | G28: =+$AO$6*$AO$7/12 -> 7760 | H28: =+$AO$6*$AO$7/12 -> 7760 | I28: =+$AO$6*$AO$7/12 -> 7760 | ... AK28: =+$AO$6*$AO$7/12 -> 7760 | AL28: =+SUM(B28:AK28) -> 279360
A29: IT | AL29: =+SUM(B29:AK29) -> 0
A30: Office Supplies | H30: 100 | I30: 100 | J30: 100 | K30: 100 | L30: 100 | M30: 100 | N30: 100 | O30: 100 | P30: 100 | Q30: 100 | R30: 100 | S30: 100 | T30: 100 | U30: 100 | V30: 100 | W30: 100 | X30: 100 | Y30: 100 | Z30: 100 | AA30: 100 | AB30: 100 | AC30: 100 | AD30: 100 | AE30: 100 | AF30: 100 | AG30: 100 | AH30: 100 | AI30: 100 | AJ30: 100 | AK30: 100
A31: Professional Services (Attorney, agents,etc.) | C31: 0 | D31: 0 | E31: 0 | F31: 2000 | G31: 0 | H31: 0 | I31: 0 | J31: 0 | K31: 0 | L31: 0 | M31: 0 | N31: 1000 | O31: 0 | P31: 0 | Q31: 0 | R31: 0 | S31: 0 | T31: 0 | U31: 0 | V31: 0 | W31: 0 | X31: 0 | Y31: 0 | Z31: 0 | AA31: 0 | AB31: 0 | AC31: 0 | AD31: 0 | AE31: 0 | AF31: 0 | AG31: 0 | AH31: 0 | AI31: 0 | AJ31: 0 | AK31: 0
A32: Rent | AL32: =+SUM(B32:AK32) -> 0
A33: Repars and Maintenance | G33: 300 | H33: 300 | I33: 300 | J33: 300 | K33: 300 | L33: 300 | M33: 300 | N33: 300 | O33: 300 | P33: 300 | Q33: 300 | R33: 300 | S33: 300 | T33: 300 | U33: 300 | V33: 300 | W33: 300 | X33: 300 | Y33: 300 | Z33: 300 | AA33: 300 | AB33: 300 | AC33: 300 | AD33: 300 | AE33: 300 | AF33: 300 | AG33: 300 | AH33: 300 | AI33: 300 | AJ33: 300 | AK33: 300
A34: Shipping | AL34: =+SUM(B34:AK34) -> 0
A35: Taxes and Licenses (Property Tax) | C35: 1000 | D35: 1000 | E35: 1000 | F35: 1000 | G35: 1000 | H35: 1000 | I35: 1000 | J35: 1000 | K35: 1000 | L35: 1000 | M35: 1000 | N35: 1000 | O35: 1000 | P35: 1000 | Q35: 1000 | R35: 1000 | S35: 1000 | T35: 1000 | U35: 1000 | V35: 1000 | W35: 1000 | X35: 1000 | Y35: 1000 | Z35: 1000 | AA35: 1000 | AB35: 1000 | AC35: 1000 | AD35: 1000 | AE35: 1000 | AF35: 1000 | AG35: 1000 | AH35: 1000 | AI35: 1000 | AJ35: 1000 | AK35: 1000 | AL35: =+SUM(B35:AK35) -> 35000
A36: Utilities | C36: 500 | D36: 500 | E36: 500 | F36: 500 | G36: 500 | H36: 500 | I36: 500 | J36: 500 | K36: 500 | L36: 500 | M36: 500 | N36: 500 | O36: 500 | P36: 500 | Q36: 500 | R36: 500 | S36: 500 | T36: 500 | U36: 500 | V36: 500 | W36: 500 | X36: 500 | Y36: 500 | Z36: 500 | AA36: 500 | AB36: 500 | AC36: 500 | AD36: 500 | AE36: 500 | AF36: 500 | AG36: 500 | AH36: 500 | AI36: 500 | AJ36: 500 | AK36: 500 | AL36: =+SUM(B36:AK36) -> 17500
A37: Wages | B37: =+'36 Month Wages'!B50 -> 0 | C37: =+'36 Month Wages'!C50 -> 8400 | D37: =+'36 Month Wages'!D50 -> 8400 | E37: =+'36 Month Wages'!E50 -> 8400 | F37: =+'36 Month Wages'!F50 -> 8400 | G37: =+'36 Month Wages'!G50 -> 8400 | H37: =+'36 Month Wages'!H50 -> 8400 | I37: =+'36 Month Wages'!I50 -> 8400 | ... AK37: =+'36 Month Wages'!AK50 -> 1000 | AL37: =+SUM(B37:AK37) -> 205200
A38: Wages - Payroll Taxes | B38: =+B37*0.0765 -> 0 | C38: =+C37*0.0765 -> 642.6 | D38: =+D37*0.0765 -> 642.6 | E38: =+E37*0.0765 -> 642.6 | F38: =+F37*0.0765 -> 642.6 | G38: =+G37*0.0765 -> 642.6 | H38: =+H37*0.0765 -> 642.6 | I38: =+I37*0.0765 -> 642.6 | ... AK38: =+AK37*0.0765 -> 76.5 | AL38: =+SUM(B38:AK38) -> 15697.8
A39: Other | AL39: =+SUM(B39:AK39) -> 0
A40: Misc. | AL40: =+SUM(B40:AK40) -> 0
...

Sheet 36 Month Wages
A1: 36 Month Wages Forecast
B2: Month 1 | C2: Month 2 | D2: Month 3 | E2: Month 4 | F2: Month 5 | G2: Month 6 | H2: Month 7 | I2: Month 8 | J2: Month 9 | K2: Month 10 | L2: Month 11 | M2: Month 12 | N2: Month 13 | O2: Month 14 | P2: Month 15 | Q2: Month 16 | R2: Month 17 | S2: Month 18 | T2: Month 19 | U2: Month 20 | V2: Month 21 | W2: Month 22 | X2: Month 23 | Y2: Month 24 | Z2: Month 25 | AA2: Month 26 | AB2: Month 27 | AC2: Month 28 | AD2: Month 29 | AE2: Month 30 | AF2: Month 31 | AG2: Month 32 | AH2: Month 33 | AI2: Month 34 | AJ2: Month 35 | AK2: Month 36 | AN2: Assumptions
A3: Employee 1: Dave Brogan | AN3: Hourly Salary
A4: Hours | C4: 168 | D4: 168 | E4: 168 | F4: 168 | G4: 168 | H4: 168 | I4: 168 | J4: 168 | K4: 168 | L4: 168 | M4: 168 | N4: 168 | O4: 168 | P4: 168 | Q4: 168 | R4: 168 | S4: 168 | T4: 168 | U4: 168 | V4: 168 | W4: 168 | X4: 168 | Y4: 168 | Z4: 20 | AA4: 20 | AB4: 20 | AC4: 20 | AD4: 20 | AE4: 20 | AF4: 20 | AG4: 20 | AH4: 20 | AI4: 20 | AJ4: 20 | AK4: 20 | AL4: =+SUM(B4:AK4) -> 4104 | AN4: Employee 1 | AO4: 50
A5: Wages | B5: =+B4*$AO$4 -> 0 | C5: =+C4*$AO$4 -> 8400 | D5: =+D4*$AO$4 -> 8400 | E5: =+E4*$AO$4 -> 8400 | F5: =+F4*$AO$4 -> 8400 | G5: =+G4*$AO$4 -> 8400 | H5: =+H4*$AO$4 -> 8400 | I5: =+I4*$AO$4 -> 8400 | ... AK5: =+AK4*$AO$4 -> 1000 | AL5: =+SUM(B5:AK5) -> 205200 | AN5: Employee 2 | AO5: 15
AN6: Employee 3 | AO6: 15
A7: Employee 2: | AN7: Employee 4 | AO7: 15
A8: Hours | AL8: =+SUM(B8:AK8) -> 0 | AN8: Employee 5 | AO8: 15
A9: Wages | B9: =+B8*$AO$5 -> 0 | C9: =+C8*$AO$5 -> 0 | D9: =+D8*$AO$5 -> 0 | E9: =+E8*$AO$5 -> 0 | F9: =+F8*$AO$5 -> 0 | G9: =+G8*$AO$5 -> 0 | H9: =+H8*$AO$5 -> 0 | I9: =+I8*$AO$5 -> 0 | ... AK9: =+AK8*$AO$5 -> 0 | AL9: =+SUM(B9:AK9) -> 0 | AN9: Employee 6 | AO9: 15
AN10: Employee 7 | AO10: 15
A11: Employee 3: | AN11: Employee 8 | AO11: 15
A12: Hours | AL12: =+SUM(B12:AK12) -> 0 | AN12: Employee 9 | AO12: 15
A13: Wages | B13: =+B12*$AO$6 -> 0 | C13: =+C12*$AO$6 -> 0 | D13: =+D12*$AO$6 -> 0 | E13: =+E12*$AO$6 -> 0 | F13: =+F12*$AO$6 -> 0 | G13: =+G12*$AO$6 -> 0 | H13: =+H12*$AO$6 -> 0 | I13: =+I12*$AO$6 -> 0 | ... AK13: =+AK12*$AO$6 -> 0 | AL13: =+SUM(B13:AK13) -> 0 | AN13: Employee 10 | AO13: 15
AN14: Employee 11 | AO14: 15
A15: Employee 4: | AN15: Employee 12 | AO15: 15
A16: Hours | AL16: =+SUM(B16:AK16) -> 0
A17: Wages | B17: =+B16*$AO$7 -> 0 | C17: =+C16*$AO$7 -> 0 | D17: =+D16*$AO$7 -> 0 | E17: =+E16*$AO$7 -> 0 | F17: =+F16*$AO$7 -> 0 | G17: =+G16*$AO$7 -> 0 | H17: =+H16*$AO$7 -> 0 | I17: =+I16*$AO$7 -> 0 | ... AK17: =+AK16*$AO$7 -> 0 | AL17: =+SUM(B17:AK17) -> 0
A19: Employee 5:
A20: Hours | AL20: =+SUM(B20:AK20) -> 0
A21: Wages | B21: =+B20*$AO$8 -> 0 | C21: =+C20*$AO$8 -> 0 | D21: =+D20*$AO$8 -> 0 | E21: =+E20*$AO$8 -> 0 | F21: =+F20*$AO$8 -> 0 | G21: =+G20*$AO$8 -> 0 | H21: =+H20*$AO$8 -> 0 | I21: =+I20*$AO$8 -> 0 | ... AK21: =+AK20*$AO$8 -> 0 | AL21: =+SUM(B21:AK21) -> 0
A23: Employee 6:
A24: Hours | AL24: =+SUM(B24:AK24) -> 0
A25: Wages | B25: =+B24*$AO$9 -> 0 | C25: =+C24*$AO$9 -> 0 | D25: =+D24*$AO$9 -> 0 | E25: =+E24*$AO$9 -> 0 | F25: =+F24*$AO$9 -> 0 | G25: =+G24*$AO$9 -> 0 | H25: =+H24*$AO$9 -> 0 | I25: =+I24*$AO$9 -> 0 | ... AK25: =+AK24*$AO$9 -> 0 | AL25: =+SUM(B25:AK25) -> 0
A27: Employee 7:
A28: Hours | AL28: =+SUM(B28:AK28) -> 0
A29: Wages | B29: =+B28*$AO$10 -> 0 | C29: =+C28*$AO$10 -> 0 | D29: =+D28*$AO$10 -> 0 | E29: =+E28*$AO$10 -> 0 | F29: =+F28*$AO$10 -> 0 | G29: =+G28*$AO$10 -> 0 | H29: =+H28*$AO$10 -> 0 | I29: =+I28*$AO$10 -> 0 | ... AK29: =+AK28*$AO$10 -> 0 | AL29: =+SUM(B29:AK29) -> 0
A31: Employee 8:
A32: Hours | AL32: =+SUM(B32:AK32) -> 0
A33: Wages | B33: =+B32*$AO$11 -> 0 | C33: =+C32*$AO$11 -> 0 | D33: =+D32*$AO$11 -> 0 | E33: =+E32*$AO$11 -> 0 | F33: =+F32*$AO$11 -> 0 | G33: =+G32*$AO$11 -> 0 | H33: =+H32*$AO$11 -> 0 | I33: =+I32*$AO$11 -> 0 | ... AK33: =+AK32*$AO$11 -> 0 | AL33: =+SUM(B33:AK33) -> 0
A35: Employee 9:
A36: Hours | AL36: =+SUM(B36:AK36) -> 0
A37: Wages | B37: =+B36*$AO$12 -> 0 | C37: =+C36*$AO$12 -> 0 | D37: =+D36*$AO$12 -> 0 | E37: =+E36*$AO$12 -> 0 | F37: =+F36*$AO$12 -> 0 | G37: =+G36*$AO$12 -> 0 | H37: =+H36*$AO$12 -> 0 | I37: =+I36*$AO$12 -> 0 | ... AK37: =+AK36*$AO$12 -> 0 | AL37: =+SUM(B37:AK37) -> 0
A39: Employee 10:
A40: Hours | AL40: =+SUM(B40:AK40) -> 0
A41: Wages | B41: =+B40*$AO$13 -> 0 | C41: =+C40*$AO$13 -> 0 | D41: =+D40*$AO$13 -> 0 | E41: =+E40*$AO$13 -> 0 | F41: =+F40*$AO$13 -> 0 | G41: =+G40*$AO$13 -> 0 | H41: =+H40*$AO$13 -> 0 | I41: =+I40*$AO$13 -> 0 | ... AK41: =+AK40*$AO$13 -> 0 | AL41: =+SUM(B41:AK41) -> 0
A43: Employee 11:
A44: Hours | AL44: =+SUM(B44:AK44) -> 0
A45: Wages | B45: =+B44*$AO$14 -> 0 | C45: =+C44*$AO$14 -> 0 | D45: =+D44*$AO$14 -> 0 | E45: =+E44*$AO$14 -> 0 | F45: =+F44*$AO$14 -> 0 | G45: =+G44*$AO$14 -> 0 | H45: =+H44*$AO$14 -> 0 | I45: =+I44*$AO$14 -> 0 | ... AK45: =+AK44*$AO$14 -> 0 | AL45: =+SUM(B45:AK45) -> 0
A47: Employee 12:
A48: Hours | AL48: =+SUM(B48:AK48) -> 0
...

Sheet 36 Month Capital Expenditures
A1: 300 Month Capital Expenditures Forecast
B2: Month 1 | C2: Month 2 | D2: Month 3 | E2: Month 4 | F2: Month 5 | G2: Month 6 | H2: Month 7 | I2: Month 8 | J2: Month 9 | K2: Month 10 | L2: Month 11 | M2: Month 12 | N2: Month 13 | O2: Month 14 | P2: Month 15 | Q2: Month 16 | R2: Month 17 | S2: Month 18 | T2: Month 19 | U2: Month 20 | V2: Month 21 | W2: Month 22 | X2: Month 23 | Y2: Month 24 | Z2: Month 25 | AA2: Month 26 | AB2: Month 27 | AC2: Month 28 | AD2: Month 29 | AE2: Month 30 | AF2: Month 31 | AG2: Month 32 | AH2: Month 33 | AI2: Month 34 | AJ2: Month 35 | AK2: Month 36
A3: Equipment | AL3: =+SUM(B3:AK3) -> 0
A4: Improvements | B4: 500000 | AL4: =+SUM(B4:AK4) -> 500000
A5: Building | B5: 900000
A7: Equipment | B7: 10000 | AL7: =+SUM(B7:AK7) -> 10000
A8: Other | AL8: =+SUM(B8:AK8) -> 0
A9: Other | AL9: =+SUM(B9:AK9) -> 0
A10: Total Capital Expenditures | B10: =+SUM(B3:B9) -> 1410000 | C10: =+SUM(C3:C9) -> 0 | D10: =+SUM(D3:D9) -> 0 | E10: =+SUM(E3:E9) -> 0 | F10: =+SUM(F3:F9) -> 0 | G10: =+SUM(G3:G9) -> 0 | H10: =+SUM(H3:H9) -> 0 | I10: =+SUM(I3:I9) -> 0 | ... AK10: =+SUM(AK3:AK9) -> 0 | AL10: =+SUM(B10:AK10) -> 1410000
A12: Depreciation Expense | B12: =+SUM($B$10:B10)/468 -> 3012.8205 | C12: =+SUM($B$10:C10)/468 -> 3012.8205 | D12: =+SUM($B$10:D10)/468 -> 3012.8205 | E12: =+SUM($B$10:E10)/468 -> 3012.8205 | F12: =+SUM($B$10:F10)/468 -> 3012.8205 | G12: =+SUM($B$10:G10)/468 -> 3012.8205 | H12: =+SUM($B$10:H10)/468 -> 3012.8205 | I12: =+SUM($B$10:I10)/468 -> 3012.8205 | ... AK12: =+SUM($B$10:AK10)/468 -> 3012.8205 | AL12: =+SUM(B12:AK12) -> 108461.54
D15: =39*12 -> 468
